<?xml version="1.0" encoding="utf-8"?>
<!-- =================================================================================== -->
<!-- |    This document was autogenerated by xacro from urdf/wamv_gazebo.urdf.xacro    | -->
<!-- |    EDITING THIS FILE BY HAND IS NOT RECOMMENDED                                 | -->
<!-- =================================================================================== -->
<!-- Basic WAM-V with gazebo plugins for dynamics -->
<robot name="WAM-V">
  <link name="main_radar_link">
    <visual name="main_radar_visual">
      <origin rpy="0 0 0" xyz="0 0 0"/>
      <geometry>
        <mesh filename="package://wamv_description/models/radar/model.dae"/>
      </geometry>
    </visual>
    <collision name="main_radar_collision">
      <origin rpy="0 0 0" xyz="0 0 0"/>
      <geometry>
        <mesh filename="package://wamv_description/models/radar/model.dae"/>
      </geometry>
    </collision>
    <inertial>
      <origin rpy="0 0 0" xyz="0 0 0.5"/>
      <mass value="1"/>
      <inertia ixx="100" ixy="0" ixz="0" iyy="100" iyz="0" izz="100"/>
    </inertial>
  </link>
  <joint name="main_chasis_radar_joint" type="fixed">
    <origin rpy="0 0 0" xyz="-2.1 -0.1 2"/>
    <parent link="base_link"/>
    <child link="main_radar_link"/>
  </joint>
  <gazebo reference="main_radar_link">
    <sensor name="range" type="ray">
      <update_rate>10</update_rate>
      <visualize>true</visualize>
      <ray>
        <scan>
          <horizontal>
            <samples>10</samples>
            <resolution>1</resolution>
            <min_angle>-0.7</min_angle>
            <max_angle>0.7</max_angle>
          </horizontal>
        </scan>
        <range>
          <min>1</min>
          <!-- do not change (smaller values cause issues) -->
          <max>35</max>
          <!-- do not change (bigger values cause issues) -->
          <resolution>0.01</resolution>
        </range>
      </ray>
      <plugin filename="libgazebo_ros_gpu_laser.so" name="LaserRangeSensor">
        <alwaysOn>true</alwaysOn>
        <updateRate>10</updateRate>
	<topicName>RadarRange<topicName>
        <frameName>main_radar_link</frameName>
      </plugin>
    </sensor>
  </gazebo>
  <link name="base_link">
  </link>
  <joint name="dummy_joint" type="fixed">
    <parent link="base_link"/>
    <child link="dummy_link"/>
  </joint>
  <!-- Basic model of the 16' WAM-V USV -->
  <link name="dummy_link">
    <visual>
      <geometry>
        <mesh filename="package://wamv_description/models/hovercraft/model.dae"/>
      </geometry>
    </visual>
    <collision>
      <geometry>
        <mesh filename="package://wamv_description/models/hovercraft/model.dae"/>
      </geometry>
    </collision>
    <!-- Left base collisions -->
    <!--><xacro:main_collisions prefix="left" reflect="1" /><-->
    <!-- Right side collisions -->
    <!--><xacro:main_collisions prefix="right" reflect="-1" /><-->
    <!-- Top base -->
    <!-->
    <collision name="top_base">
      <origin xyz="0 -0 1.25" rpy="0 0 0" />
      <geometry>
        <box size="1.85 1 0.1" />
      </geometry>
    </collision>
<-->
    <inertial>
      <!-- From WAM-V spec sheet -->
      <mass value="180.0"/>
      <inertia ixx="120.0" ixy="0.0" ixz="0.0" iyy="393" iyz="0.0" izz="446.0"/>
    </inertial>
  </link>
  <link name="left_engine_link">
    <visual>
      <geometry>
        <mesh filename="package://wamv_description/models/engine/mesh/engine.dae"/>
      </geometry>
    </visual>
    <collision name="left_engine_vertical_axis_collision">
      <origin rpy="0 0 0" xyz="-0.16 0 -0.24"/>
      <geometry>
        <box size="0.2 0.15 0.83"/>
      </geometry>
    </collision>
    <collision name="left_engine_rear_end_collision">
      <origin rpy="0 0 0" xyz="-0.34 0 0.12"/>
      <geometry>
        <box size="0.12 0.15 0.12"/>
      </geometry>
    </collision>
    <inertial>
      <mass value="15"/>
      <inertia ixx="0.889245" ixy="0.0" ixz="0.0" iyy="0.911125" iyz="0.0" izz="0.078125"/>
    </inertial>
  </link>
  <link name="left_propeller_link">
    <visual>
      <geometry>
        <mesh filename="package://wamv_description/models/propeller/mesh/propeller.dae"/>
      </geometry>
    </visual>
    <collision name="left_propeller_collision">
      <origin rpy="0 1.57 0" xyz="-0.08 0 0"/>
      <geometry>
        <cylinder length="0.18" radius="0.24"/>
      </geometry>
    </collision>
    <inertial>
      <mass value="0.5"/>
      <inertia ixx="0.008545" ixy="0.0" ixz="0.0" iyy="0.008545" iyz="0.0" izz="0.0144"/>
    </inertial>
  </link>
  <joint name="left_chasis_engine_joint" type="revolute">
    <axis xyz="0 0 1"/>
    <limit effort="10" lower="-3.14159265359" upper="3.14159265359" velocity="10"/>
    <origin rpy="0 0 0" xyz="-2.373776 1.027135 0.318237"/>
    <parent link="base_link"/>
    <child link="left_engine_link"/>
  </joint>
  <joint name="left_engine_propeller_joint" type="continuous">
    <axis rpy="0 0 0" xyz="1 0 0"/>
    <parent link="left_engine_link"/>
    <child link="left_propeller_link"/>
    <origin rpy="0 0 0" xyz="-0.278156 0 -0.509371"/>
    <limit effort="100" velocity="100"/>
    <dynamics damping="0.05" friction="0.05"/>
  </joint>
  <link name="right_engine_link">
    <visual>
      <geometry>
        <mesh filename="package://wamv_description/models/engine/mesh/engine.dae"/>
      </geometry>
    </visual>
    <collision name="right_engine_vertical_axis_collision">
      <origin rpy="0 0 0" xyz="-0.16 0 -0.24"/>
      <geometry>
        <box size="0.2 0.15 0.83"/>
      </geometry>
    </collision>
    <collision name="right_engine_rear_end_collision">
      <origin rpy="0 0 0" xyz="-0.34 0 0.12"/>
      <geometry>
        <box size="0.12 0.15 0.12"/>
      </geometry>
    </collision>
    <inertial>
      <mass value="15"/>
      <inertia ixx="0.889245" ixy="0.0" ixz="0.0" iyy="0.911125" iyz="0.0" izz="0.078125"/>
    </inertial>
  </link>
  <link name="right_propeller_link">
    <visual>
      <geometry>
        <mesh filename="package://wamv_description/models/propeller/mesh/propeller.dae"/>
      </geometry>
    </visual>
    <collision name="right_propeller_collision">
      <origin rpy="0 1.57 0" xyz="-0.08 0 0"/>
      <geometry>
        <cylinder length="0.18" radius="0.24"/>
      </geometry>
    </collision>
    <inertial>
      <mass value="0.5"/>
      <inertia ixx="0.008545" ixy="0.0" ixz="0.0" iyy="0.008545" iyz="0.0" izz="0.0144"/>
    </inertial>
  </link>
  <joint name="right_chasis_engine_joint" type="revolute">
    <axis xyz="0 0 1"/>
    <limit effort="10" lower="-3.14159265359" upper="3.14159265359" velocity="10"/>
    <origin rpy="0 0 0" xyz="-2.373776 -1.027135 0.318237"/>
    <parent link="base_link"/>
    <child link="right_engine_link"/>
  </joint>
  <joint name="right_engine_propeller_joint" type="continuous">
    <axis rpy="0 0 0" xyz="1 0 0"/>
    <parent link="right_engine_link"/>
    <child link="right_propeller_link"/>
    <origin rpy="0 0 0" xyz="-0.278156 0 -0.509371"/>
    <limit effort="100" velocity="100"/>
    <dynamics damping="0.05" friction="0.05"/>
  </joint>
  <gazebo>
    <plugin filename="libusv_gazebo_thrust_plugin.so" name="wamv_gazebo_thrust">
      <cmdTimeout>1.0</cmdTimeout>
      <robotNamespace>wamv</robotNamespace>
      <thruster>
        <!-- Required Parameters -->
        <linkName>left_propeller_link</linkName>
        <propJointName>left_engine_propeller_joint</propJointName>
        <engineJointName>left_chasis_engine_joint</engineJointName>
        <cmdTopic>thrusters/left_thrust_cmd</cmdTopic>
        <angleTopic>thrusters/left_thrust_angle</angleTopic>
        <enableAngle>true</enableAngle>
        <!-- Optional Parameters -->
        <mappingType>1</mappingType>
        <maxCmd>1.0</maxCmd>
        <maxForceFwd>250.0</maxForceFwd>
        <maxForceRev>-100.0</maxForceRev>
        <maxAngle>1.57079632679</maxAngle>
      </thruster>
      <thruster>
        <!-- Required Parameters -->
        <linkName>right_propeller_link</linkName>
        <propJointName>right_engine_propeller_joint</propJointName>
        <engineJointName>right_chasis_engine_joint</engineJointName>
        <cmdTopic>thrusters/right_thrust_cmd</cmdTopic>
        <angleTopic>thrusters/right_thrust_angle</angleTopic>
        <enableAngle>true</enableAngle>
        <!-- Optional Parameters -->
        <mappingType>1</mappingType>
        <maxCmd>1.0</maxCmd>
        <maxForceFwd>250.0</maxForceFwd>
        <maxForceRev>-100.0</maxForceRev>
        <maxAngle>1.57079632679</maxAngle>
      </thruster>
    </plugin>
  </gazebo>
  <!--Gazebo Plugin for simulating WAM-V dynamics-->
  <gazebo>
    <plugin filename="libusv_gazebo_dynamics_plugin.so" name="usv_dynamics_wamv_dynamics_plugin">
      <bodyName>base_link</bodyName>
      <!-- Must be same as the ocean model!-->
      <waterLevel>0</waterLevel>
      <waterDensity>997.8</waterDensity>
      <!-- Added mass -->
      <xDotU>0.0</xDotU>
      <yDotV>0.0</yDotV>
      <nDotR>0.0</nDotR>
      <!-- Linear and quadratic drag -->
      <xU>51.3</xU>
      <xUU>72.4</xUU>
      <yV>40.0</yV>
      <yVV>0.0</yVV>
      <zW>500.0</zW>
      <kP>50.0</kP>
      <mQ>50.0</mQ>
      <nR>400.0</nR>
      <nRR>0.0</nRR>
      <!-- General dimensions -->
      <!--<boatArea>2.2</boatArea>-->
      <hullRadius>0.213</hullRadius>
      <boatWidth>2.4</boatWidth>
      <boatLength>4.9</boatLength>
      <!-- Length discretization, AKA, "N" -->
      <length_n>2</length_n>
      <!-- Wave model -->
      <wave_model>ocean_waves</wave_model>
    </plugin>
  </gazebo>
</robot>
